Workbook
Name L_MixNom: Listes!$A$2:$A$8
Name L_MixVal: Listes!$B$2:$B$8
Name L_MixSrc: Listes!$C$2:$C$8
Name D_Date: 'Données'!$A:$A
Name D_Prod: 'Données'!$C:$C
Name D_I: 'Données'!$S:$S
Name D_O: 'Données'!$T:$T
Name D_CR: 'Données'!$U:$U
Name D_CW: 'Données'!$V:$V
Name D_Mod: 'Données'!$W:$W
Name D_Jour: 'Données'!$X:$X
Name D_Cle: 'Données'!$Y:$Y
Name D_Grp: 'Données'!$AA:$AA
Name D_TO: 'Données'!$AC:$AC
Name D_kWh: 'Données'!$AD:$AD
Name D_CO2: 'Données'!$AE:$AE
Name D_Brut: 'Données'!$AF:$AF
Name D_An: 'Données'!$AG:$AG
Name D_Mois: 'Données'!$AH:$AH
Name D_C2: 'Données'!$AI:$AI
Name D_C4F: 'Données'!$AJ:$AJ
Name D_C4CW: 'Données'!$AK:$AK
Name P_Source: Calcul!$C$6
Name P_MixNom: Calcul!$C$7
Name P_MixPerso: Calcul!$C$8
Name P_Mix: Calcul!$C$9
Name P_Fab: Calcul!$C$10
Name P_Lo: Calcul!$C$11
Name P_Hi: Calcul!$C$12
Name P_N: Calcul!$C$13
Name P_Adj: Calcul!$C$14
Name M_Nom: Calcul!$B$30:$B$118
Name M_Fam: Calcul!$C$30:$C$118
Name M_Force: Calcul!$D$30:$D$118
Name M_Conv: Calcul!$E$30:$E$118
Name M_Orig: Calcul!$F$30:$F$118
Name M_Delta: Calcul!$G$30:$G$118
Name M_Eps: Calcul!$H$30:$H$118
Name M_PI: Calcul!$I$30:$I$118
Name M_PCR: Calcul!$J$30:$J$118
Name M_PCW: Calcul!$K$30:$K$118
Name M_PO: Calcul!$L$30:$L$118
Name M_Avant: Calcul!$M$30:$M$118
Name M_sI: Calcul!$N$30:$N$118
Name M_sCR: Calcul!$O$30:$O$118
Name M_sCW: Calcul!$P$30:$P$118
Name M_Scen: Calcul!$Q$30:$Q$118
Name M_eO: Calcul!$R$30:$R$118
Name M_PUE: Calcul!$S$30:$S$118
Name M_Fab: Calcul!$T$30:$T$118
Name M_FET: Calcul!$U$30:$U$118
Name M_Stat: Calcul!$V$30:$V$118
Name M_FEF: Calcul!$W$30:$W$118
Name M_FEC: Calcul!$X$30:$X$118
Name M_FE: Calcul!$Y$30:$Y$118
Name M_Src: Calcul!$Z$30:$Z$118
Name F_Fam: Calcul!$G$7:$G$14
Name F_Conv: Calcul!$H$7:$H$14
Name S_Has: Interne!$C$4
Name S_Last: Interne!$C$5

Sheet Mode d'emploi
B2: Mode d'emploi
B3: Déclinaison Excel du tableau de bord « Empreinte carbone de GitHub Copilot ».
B5: 1 | C5: Exportez le rapport d'usage Copilot (CSV « AI usage report ») depuis GitHub.
B6: 2 | C6: Dans l'onglet Données, videz l'ancien contenu s'il y en a : sélectionnez les lignes du tableau sous l'en-tête, clic droit › Supprimer › Lignes du tableau.
B7: 3 | C7: Ouvrez le CSV, copiez toutes les lignes sous l'en-tête (colonnes date à cache_write, dans l'ordre de l'export) et collez-les en A2 de l'onglet Données. Le tableau s'agrandit et les colonnes bleues se calculent seules. Si les nombres décimaux sont mal lus (Excel en français), passez par Données › À partir d'un fichier texte/CSV, avec « Origine du fichier » 65001 : Unicode (UTF-8) et la virgule comme délimiteur, puis copiez le résultat.
B8: 4 | C8: Ouvrez l'onglet Synthèse. L'année affichée est la dernière des données ; tapez une autre année dans la cellule jaune pour changer.
B9: 5 | C9: Réglez les hypothèses dans l'onglet Calcul (source des facteurs, mix électrique, fabrication, fourchette, projection, paramètres par modèle). Vérifiez l'onglet Contrôles après chaque nouvel import, en particulier les modèles inconnus (C1).
B11: Légende
C12: Cellule jaune, texte bleu : saisie ou hypothèse modifiable.
C13: En-tête bleu dans Données : colonne calculée, ne pas modifier.
C14: Tout le reste est calculé par formules. Les tokens s'affichent en k, M et Mds ; les émissions en kg puis en t au-delà de 1 000 kg.
B16: Format attendu (une ligne d'exemple, ne pas la coller)
C17: date : 2026-10-21
C18: username : jdupont
C19: product : copilot
C20: sku : copilot_ai_credits
C21: model : Claude Sonnet 4.6
C22: quantity : 168.25
C23: unit-type : ai-credits
C24: applied_cost_per_quantity : 0.04
C25: gross_amount : 6.73
C26: discount_amount : 0
C27: net_amount : 6.73
C28: total_monthly_quota : (vide)
... C38: cache_write : 509724
B40: Onglets
C41: • Synthèse : indicateurs clés de l'année, tendance, graphique mensuel, modèles les plus émetteurs, phrases à retenir.
C42: • Empreinte : tableau mois par mois (réel et projeté), répartition par modèle, cumul, série quotidienne, classement complet des modèles.
C43: • Calcul : formules, réglages globaux et paramètres par modèle (prix, convention, e_O, facteurs).
C44: • Contrôles : C1 à C6.
C45: • Méthodologie : sources et choix de méthode.
C46: • Données : l'export collé et les colonnes calculées.
C47: • Interne et Listes : calculs intermédiaires et listes de choix, à ne pas modifier.

Sheet Synthèse
B2: Empreinte carbone de GitHub Copilot
B3: ="Inférence des modèles utilisés via Copilot · facteurs : "&P_Source&" · méthode du 20/10/2026" -> Inférence des modèles utilisés via Copilot · facteurs : Table fournie · méthode du 20/10/2026
B4: =IF(S_Has,"Données du "&RIGHT("0"&DAY(S_First),2)&"/"&RIGHT("0"&MONTH(S_First),2)&"/"&YEAR(S_First)&" au "&RIGHT("0"&DAY(S_Last),2)&"/"&RIGHT("0"&MONTH(S_Last),2)&"/"&YEAR(S_Last)&" · "&FIXED(COUNT(D_Jour),0)&" lignes","Aucune donnée : collez votre export dans l'onglet Données (voir Mode d'emploi).") -> Aucune donnée : collez votre export dans l'onglet Données (voir Mode d'emploi).
B6: Année | C6: =YEAR(IF(COUNT(D_Jour)>0,MAX(D_Jour),TODAY())) -> 2026 | D6: ← saisissez une autre année pour changer toute la synthèse et l'onglet Empreinte (par défaut : la dernière année des données).
B8: ="Émissions "&S_An -> Émissions 2026 | E8: =IF(S_Cur,"Atterrissage fin "&S_An,"Bilan "&S_An) -> Bilan 2026 | H8: Tokens équivalent output | K8: Coût brut
B9: =S_YTD -> 0 | E9: =S_Land -> 0 | H9: =S_TO -> 0 | K9: =S_Brut -> 0
B10: ="Fourchette "&IF(S_YTD*P_Lo>=1000,FIXED(S_YTD*P_Lo/1000,2)&" t",FIXED(S_YTD*P_Lo,1)&" kg")&" – "&IF(S_YTD*P_Hi>=1000,FIXED(S_YTD*P_Hi/1000,2)&" t",FIXED(S_YTD*P_Hi,1)&" kg") -> Fourchette 0.0 kg – 0.0 kg | E10: =IF(S_Cur,"Déjà émis "&IF(S_YTD>=1000,FIXED(S_YTD/1000,2)&" t",FIXED(S_YTD,1)&" kg")&" · fourchette "&IF(S_Land*P_Lo>=1000,FIXED(S_Land*P_Lo/1000,2)&" t",FIXED(S_Land*P_Lo,1)&" kg")&" – "&IF(S_Land*P_Hi>=1000,FIXED(S_Land*P_Hi/1000,2)&" t",FIXED(S_Land*P_Hi,1)&" kg"),"Année close : émissions réelles") -> Année close : émissions réelles | H10: ="Énergie "&IF(S_kWh>=1000,FIXED(S_kWh/1000,2)&" MWh",FIXED(S_kWh,1)&" kWh")&" (e_O × PUE, EcoLogits v2)" -> Énergie 0.0 kWh (e_O × PUE, EcoLogits v2) | K10: =IF(S_Brut>0,FIXED(S_YTD*1000/S_Brut,1)&" gCO₂e par dollar","Pas de montant dans l'export") -> Pas de montant dans l'export
B12: Tendance
B13: =IF(S_Cur,S_An&" à date vs même période "&(S_An-1),S_An&" vs "&(S_An-1)) -> 2026 vs 2025 | F13: ="Dernier mois complet ("&INDEX(L_Mois,MONTH(S_LCM))&" "&YEAR(S_LCM)&") vs "&(YEAR(S_LCM)-1) -> Dernier mois complet (déc. 2026) vs 2025 | J13: ="Projection "&S_An&" vs "&(S_An-1) -> Projection 2026 vs 2025
B14: =IF(S_PrevSame>0,S_CurSame/S_PrevSame-1,"—") -> — | F14: =IF(S_LCMp>0,S_LCMv/S_LCMp-1,"—") -> — | J14: =IF(S_PrevTot>0,S_Land/S_PrevTot-1,"—") -> —
B15: =IF(S_CurSame>=1000,FIXED(S_CurSame/1000,2)&" t",FIXED(S_CurSame,1)&" kg")&" CO₂e"&" contre "&IF(S_PrevSame>=1000,FIXED(S_PrevSame/1000,2)&" t",FIXED(S_PrevSame,1)&" kg")&" CO₂e" -> 0.0 kg CO₂e contre 0.0 kg CO₂e | F15: =IF(S_LCMv>=1000,FIXED(S_LCMv/1000,2)&" t",FIXED(S_LCMv,1)&" kg")&" CO₂e"&" contre "&IF(S_LCMp>=1000,FIXED(S_LCMp/1000,2)&" t",FIXED(S_LCMp,1)&" kg")&" CO₂e" -> 0.0 kg CO₂e contre 0.0 kg CO₂e | J15: =IF(S_Cur,"Rythme des "&P_N&" derniers jours : "&FIXED(S_Rate,2)&" kg/jour","Bilan "&S_An&" contre "&IF(S_PrevTot>=1000,FIXED(S_PrevTot/1000,2)&" t",FIXED(S_PrevTot,1)&" kg")&" CO₂e"&" en "&(S_An-1)) -> Bilan 2026 contre 0.0 kg CO₂e en 2025
B17: Émissions mensuelles
B36: Modèles les plus émetteurs
B37: Rang | C37: Modèle | G37: kgCO₂e | I37: Part | J37: Source du FE
B38: =Empreinte!B40 | C38: =Empreinte!C40 | G38: =Empreinte!D40 | I38: =Empreinte!E40 | J38: =Empreinte!K40
B39: =Empreinte!B41 | C39: =Empreinte!C41 | G39: =Empreinte!D41 | I39: =Empreinte!E41 | J39: =Empreinte!K41
B40: =Empreinte!B42 | C40: =Empreinte!C42 | G40: =Empreinte!D42 | I40: =Empreinte!E42 | J40: =Empreinte!K42
B41: =Empreinte!B43 | C41: =Empreinte!C43 | G41: =Empreinte!D43 | I41: =Empreinte!E43 | J41: =Empreinte!K43
B42: =Empreinte!B44 | C42: =Empreinte!C44 | G42: =Empreinte!D44 | I42: =Empreinte!E44 | J42: =Empreinte!K44
B45: À retenir
B46: =IF(S_Has,"En "&S_An&", l'usage de GitHub Copilot a émis "&IF(S_YTD>=1000,FIXED(S_YTD/1000,2)&" t",FIXED(S_YTD,1)&" kg")&" CO₂e"&" (fourchette "&IF(S_YTD*P_Lo>=1000,FIXED(S_YTD*P_Lo/1000,2)&" t",FIXED(S_YTD*P_Lo,1)&" kg")&" CO₂e"&" à "&IF(S_YTD*P_Hi>=1000,FIXED(S_YTD*P_Hi/1000,2)&" t",FIXED(S_YTD*P_Hi,1)&" kg")&" CO₂e"&") pour "&IF(S_TO>=1000000000,FIXED(S_TO/1000000000,1)&" Mds",FIXED(S_TO/1000000,1)&" M")&" de tokens équivalent output.","Importez un export pour obtenir la synthèse.") -> Importez un export pour obtenir la synthèse.
B47: =IF(Empreinte!C40="","","Le premier modèle, "&Empreinte!C40&", représente "&FIXED(Empreinte!E40*100,0)&" % des émissions de l'année ; les cinq premiers en représentent "&FIXED(SUM(Empreinte!E40:E44)*100,0)&" %.")
B48: =IF(NOT(S_Has),"",IF(S_Cur,"Au rythme des "&P_N&" derniers jours, l'année se terminerait vers "&IF(S_Land>=1000,FIXED(S_Land/1000,2)&" t",FIXED(S_Land,1)&" kg")&" CO₂e"&IF(S_PrevTot>0," ("&IF(S_Land>=S_PrevTot,"+","")&FIXED((S_Land/S_PrevTot-1)*100,0)&" % par rapport à "&(S_An-1)&").","."),"L'année "&S_An&" est close : bilan de "&IF(S_YTD>=1000,FIXED(S_YTD/1000,2)&" t",FIXED(S_YTD,1)&" kg")&" CO₂e"&"."))
B49: =IF(S_Brut>0,"Intensité : "&FIXED(S_YTD*1000/S_Brut,1)&" gCO₂e par dollar facturé (montant brut).","")

Sheet Empreinte
B2: Empreinte
B3: ="Année "&S_An&" · facteurs : "&P_Source&" · mix "&P_MixNom&IF(S_Cur," · projection au rythme des "&P_N&" derniers jours","") -> Année 2026 · facteurs : Table fournie · mix France (2020, EEA)
B5: Mois par mois
B6: Mois | C6: Réel (kgCO₂e) | D6: Projeté (kgCO₂e) | E6: Total (kgCO₂e) | F6: Cumul réel | G6: Cumul projeté | H6: Énergie | I6: Tokens éq. output | J6: Coût brut | K6: gCO₂e par $
B7: janv. | C7: =SUMIFS(D_CO2,D_An,S_An,D_Mois,1) -> 0 | D7: =IF(S_Cur,S_Rate*MAX(0,EOMONTH(DATE(S_An,1,1),0)-MAX(S_Last,DATE(S_An,1,1)-1)),0) -> 0 | E7: =C7+D7 -> 0 | F7: =SUM(C$7:C7) -> 0 | G7: =SUM(D$7:D7) -> 0 | H7: =SUMIFS(D_kWh,D_An,S_An,D_Mois,1) -> 0 | I7: =SUMIFS(D_TO,D_An,S_An,D_Mois,1) -> 0 | J7: =SUMIFS(D_Brut,D_An,S_An,D_Mois,1) -> 0 | K7: =IF(J7>0,C7*1000/J7,"")
B8: févr. | C8: =SUMIFS(D_CO2,D_An,S_An,D_Mois,2) -> 0 | D8: =IF(S_Cur,S_Rate*MAX(0,EOMONTH(DATE(S_An,2,1),0)-MAX(S_Last,DATE(S_An,2,1)-1)),0) -> 0 | E8: =C8+D8 -> 0 | F8: =SUM(C$7:C8) -> 0 | G8: =SUM(D$7:D8) -> 0 | H8: =SUMIFS(D_kWh,D_An,S_An,D_Mois,2) -> 0 | I8: =SUMIFS(D_TO,D_An,S_An,D_Mois,2) -> 0 | J8: =SUMIFS(D_Brut,D_An,S_An,D_Mois,2) -> 0 | K8: =IF(J8>0,C8*1000/J8,"")
B9: mars | C9: =SUMIFS(D_CO2,D_An,S_An,D_Mois,3) -> 0 | D9: =IF(S_Cur,S_Rate*MAX(0,EOMONTH(DATE(S_An,3,1),0)-MAX(S_Last,DATE(S_An,3,1)-1)),0) -> 0 | E9: =C9+D9 -> 0 | F9: =SUM(C$7:C9) -> 0 | G9: =SUM(D$7:D9) -> 0 | H9: =SUMIFS(D_kWh,D_An,S_An,D_Mois,3) -> 0 | I9: =SUMIFS(D_TO,D_An,S_An,D_Mois,3) -> 0 | J9: =SUMIFS(D_Brut,D_An,S_An,D_Mois,3) -> 0 | K9: =IF(J9>0,C9*1000/J9,"")
B10: avr. | C10: =SUMIFS(D_CO2,D_An,S_An,D_Mois,4) -> 0 | D10: =IF(S_Cur,S_Rate*MAX(0,EOMONTH(DATE(S_An,4,1),0)-MAX(S_Last,DATE(S_An,4,1)-1)),0) -> 0 | E10: =C10+D10 -> 0 | F10: =SUM(C$7:C10) -> 0 | G10: =SUM(D$7:D10) -> 0 | H10: =SUMIFS(D_kWh,D_An,S_An,D_Mois,4) -> 0 | I10: =SUMIFS(D_TO,D_An,S_An,D_Mois,4) -> 0 | J10: =SUMIFS(D_Brut,D_An,S_An,D_Mois,4) -> 0 | K10: =IF(J10>0,C10*1000/J10,"")
B11: mai | C11: =SUMIFS(D_CO2,D_An,S_An,D_Mois,5) -> 0 | D11: =IF(S_Cur,S_Rate*MAX(0,EOMONTH(DATE(S_An,5,1),0)-MAX(S_Last,DATE(S_An,5,1)-1)),0) -> 0 | E11: =C11+D11 -> 0 | F11: =SUM(C$7:C11) -> 0 | G11: =SUM(D$7:D11) -> 0 | H11: =SUMIFS(D_kWh,D_An,S_An,D_Mois,5) -> 0 | I11: =SUMIFS(D_TO,D_An,S_An,D_Mois,5) -> 0 | J11: =SUMIFS(D_Brut,D_An,S_An,D_Mois,5) -> 0 | K11: =IF(J11>0,C11*1000/J11,"")
B12: juin | C12: =SUMIFS(D_CO2,D_An,S_An,D_Mois,6) -> 0 | D12: =IF(S_Cur,S_Rate*MAX(0,EOMONTH(DATE(S_An,6,1),0)-MAX(S_Last,DATE(S_An,6,1)-1)),0) -> 0 | E12: =C12+D12 -> 0 | F12: =SUM(C$7:C12) -> 0 | G12: =SUM(D$7:D12) -> 0 | H12: =SUMIFS(D_kWh,D_An,S_An,D_Mois,6) -> 0 | I12: =SUMIFS(D_TO,D_An,S_An,D_Mois,6) -> 0 | J12: =SUMIFS(D_Brut,D_An,S_An,D_Mois,6) -> 0 | K12: =IF(J12>0,C12*1000/J12,"")
B13: juil. | C13: =SUMIFS(D_CO2,D_An,S_An,D_Mois,7) -> 0 | D13: =IF(S_Cur,S_Rate*MAX(0,EOMONTH(DATE(S_An,7,1),0)-MAX(S_Last,DATE(S_An,7,1)-1)),0) -> 0 | E13: =C13+D13 -> 0 | F13: =SUM(C$7:C13) -> 0 | G13: =SUM(D$7:D13) -> 0 | H13: =SUMIFS(D_kWh,D_An,S_An,D_Mois,7) -> 0 | I13: =SUMIFS(D_TO,D_An,S_An,D_Mois,7) -> 0 | J13: =SUMIFS(D_Brut,D_An,S_An,D_Mois,7) -> 0 | K13: =IF(J13>0,C13*1000/J13,"")
B14: août | C14: =SUMIFS(D_CO2,D_An,S_An,D_Mois,8) -> 0 | D14: =IF(S_Cur,S_Rate*MAX(0,EOMONTH(DATE(S_An,8,1),0)-MAX(S_Last,DATE(S_An,8,1)-1)),0) -> 0 | E14: =C14+D14 -> 0 | F14: =SUM(C$7:C14) -> 0 | G14: =SUM(D$7:D14) -> 0 | H14: =SUMIFS(D_kWh,D_An,S_An,D_Mois,8) -> 0 | I14: =SUMIFS(D_TO,D_An,S_An,D_Mois,8) -> 0 | J14: =SUMIFS(D_Brut,D_An,S_An,D_Mois,8) -> 0 | K14: =IF(J14>0,C14*1000/J14,"")
B15: sept. | C15: =SUMIFS(D_CO2,D_An,S_An,D_Mois,9) -> 0 | D15: =IF(S_Cur,S_Rate*MAX(0,EOMONTH(DATE(S_An,9,1),0)-MAX(S_Last,DATE(S_An,9,1)-1)),0) -> 0 | E15: =C15+D15 -> 0 | F15: =SUM(C$7:C15) -> 0 | G15: =SUM(D$7:D15) -> 0 | H15: =SUMIFS(D_kWh,D_An,S_An,D_Mois,9) -> 0 | I15: =SUMIFS(D_TO,D_An,S_An,D_Mois,9) -> 0 | J15: =SUMIFS(D_Brut,D_An,S_An,D_Mois,9) -> 0 | K15: =IF(J15>0,C15*1000/J15,"")
B16: oct. | C16: =SUMIFS(D_CO2,D_An,S_An,D_Mois,10) -> 0 | D16: =IF(S_Cur,S_Rate*MAX(0,EOMONTH(DATE(S_An,10,1),0)-MAX(S_Last,DATE(S_An,10,1)-1)),0) -> 0 | E16: =C16+D16 -> 0 | F16: =SUM(C$7:C16) -> 0 | G16: =SUM(D$7:D16) -> 0 | H16: =SUMIFS(D_kWh,D_An,S_An,D_Mois,10) -> 0 | I16: =SUMIFS(D_TO,D_An,S_An,D_Mois,10) -> 0 | J16: =SUMIFS(D_Brut,D_An,S_An,D_Mois,10) -> 0 | K16: =IF(J16>0,C16*1000/J16,"")
B17: nov. | C17: =SUMIFS(D_CO2,D_An,S_An,D_Mois,11) -> 0 | D17: =IF(S_Cur,S_Rate*MAX(0,EOMONTH(DATE(S_An,11,1),0)-MAX(S_Last,DATE(S_An,11,1)-1)),0) -> 0 | E17: =C17+D17 -> 0 | F17: =SUM(C$7:C17) -> 0 | G17: =SUM(D$7:D17) -> 0 | H17: =SUMIFS(D_kWh,D_An,S_An,D_Mois,11) -> 0 | I17: =SUMIFS(D_TO,D_An,S_An,D_Mois,11) -> 0 | J17: =SUMIFS(D_Brut,D_An,S_An,D_Mois,11) -> 0 | K17: =IF(J17>0,C17*1000/J17,"")
B18: déc. | C18: =SUMIFS(D_CO2,D_An,S_An,D_Mois,12) -> 0 | D18: =IF(S_Cur,S_Rate*MAX(0,EOMONTH(DATE(S_An,12,1),0)-MAX(S_Last,DATE(S_An,12,1)-1)),0) -> 0 | E18: =C18+D18 -> 0 | F18: =SUM(C$7:C18) -> 0 | G18: =SUM(D$7:D18) -> 0 | H18: =SUMIFS(D_kWh,D_An,S_An,D_Mois,12) -> 0 | I18: =SUMIFS(D_TO,D_An,S_An,D_Mois,12) -> 0 | J18: =SUMIFS(D_Brut,D_An,S_An,D_Mois,12) -> 0 | K18: =IF(J18>0,C18*1000/J18,"")
B19: Total | C19: =SUM(C7:C18) -> 0 | D19: =SUM(D7:D18) -> 0 | E19: =SUM(E7:E18) -> 0 | H19: =SUM(H7:H18) -> 0 | I19: =SUM(I7:I18) -> 0 | J19: =SUM(J7:J18) -> 0 | K19: =IF(J19>0,C19*1000/J19,"")
B20: Projeté : rythme quotidien moyen des derniers jours (réglage dans Calcul), appliqué aux jours restants jusqu'au 31 décembre.
B22: Par modèle (8 premiers modèles de l'année + autres), kgCO₂e
B23: Mois | C23: =IF(INDEX(I_Top,1)="","—",INDEX(I_Top,1)) -> — | D23: =IF(INDEX(I_Top,2)="","—",INDEX(I_Top,2)) -> — | E23: =IF(INDEX(I_Top,3)="","—",INDEX(I_Top,3)) -> — | F23: =IF(INDEX(I_Top,4)="","—",INDEX(I_Top,4)) -> — | G23: =IF(INDEX(I_Top,5)="","—",INDEX(I_Top,5)) -> — | H23: =IF(INDEX(I_Top,6)="","—",INDEX(I_Top,6)) -> — | I23: =IF(INDEX(I_Top,7)="","—",INDEX(I_Top,7)) -> — | J23: =IF(INDEX(I_Top,8)="","—",INDEX(I_Top,8)) -> — | K23: Autres
B24: janv. | C24: =IF(INDEX(I_Top,1)="",0,SUMIFS(D_CO2,D_Grp,INDEX(I_Top,1),D_An,S_An,D_Mois,1)) -> 0 | D24: =IF(INDEX(I_Top,2)="",0,SUMIFS(D_CO2,D_Grp,INDEX(I_Top,2),D_An,S_An,D_Mois,1)) -> 0 | E24: =IF(INDEX(I_Top,3)="",0,SUMIFS(D_CO2,D_Grp,INDEX(I_Top,3),D_An,S_An,D_Mois,1)) -> 0 | F24: =IF(INDEX(I_Top,4)="",0,SUMIFS(D_CO2,D_Grp,INDEX(I_Top,4),D_An,S_An,D_Mois,1)) -> 0 | G24: =IF(INDEX(I_Top,5)="",0,SUMIFS(D_CO2,D_Grp,INDEX(I_Top,5),D_An,S_An,D_Mois,1)) -> 0 | H24: =IF(INDEX(I_Top,6)="",0,SUMIFS(D_CO2,D_Grp,INDEX(I_Top,6),D_An,S_An,D_Mois,1)) -> 0 | I24: =IF(INDEX(I_Top,7)="",0,SUMIFS(D_CO2,D_Grp,INDEX(I_Top,7),D_An,S_An,D_Mois,1)) -> 0 | J24: =IF(INDEX(I_Top,8)="",0,SUMIFS(D_CO2,D_Grp,INDEX(I_Top,8),D_An,S_An,D_Mois,1)) -> 0 | K24: =MAX(0,C7-SUM(C24:J24)) -> 0
B25: févr. | C25: =IF(INDEX(I_Top,1)="",0,SUMIFS(D_CO2,D_Grp,INDEX(I_Top,1),D_An,S_An,D_Mois,2)) -> 0 | D25: =IF(INDEX(I_Top,2)="",0,SUMIFS(D_CO2,D_Grp,INDEX(I_Top,2),D_An,S_An,D_Mois,2)) -> 0 | E25: =IF(INDEX(I_Top,3)="",0,SUMIFS(D_CO2,D_Grp,INDEX(I_Top,3),D_An,S_An,D_Mois,2)) -> 0 | F25: =IF(INDEX(I_Top,4)="",0,SUMIFS(D_CO2,D_Grp,INDEX(I_Top,4),D_An,S_An,D_Mois,2)) -> 0 | G25: =IF(INDEX(I_Top,5)="",0,SUMIFS(D_CO2,D_Grp,INDEX(I_Top,5),D_An,S_An,D_Mois,2)) -> 0 | H25: =IF(INDEX(I_Top,6)="",0,SUMIFS(D_CO2,D_Grp,INDEX(I_Top,6),D_An,S_An,D_Mois,2)) -> 0 | I25: =IF(INDEX(I_Top,7)="",0,SUMIFS(D_CO2,D_Grp,INDEX(I_Top,7),D_An,S_An,D_Mois,2)) -> 0 | J25: =IF(INDEX(I_Top,8)="",0,SUMIFS(D_CO2,D_Grp,INDEX(I_Top,8),D_An,S_An,D_Mois,2)) -> 0 | K25: =MAX(0,C8-SUM(C25:J25)) -> 0
B26: mars | C26: =IF(INDEX(I_Top,1)="",0,SUMIFS(D_CO2,D_Grp,INDEX(I_Top,1),D_An,S_An,D_Mois,3)) -> 0 | D26: =IF(INDEX(I_Top,2)="",0,SUMIFS(D_CO2,D_Grp,INDEX(I_Top,2),D_An,S_An,D_Mois,3)) -> 0 | E26: =IF(INDEX(I_Top,3)="",0,SUMIFS(D_CO2,D_Grp,INDEX(I_Top,3),D_An,S_An,D_Mois,3)) -> 0 | F26: =IF(INDEX(I_Top,4)="",0,SUMIFS(D_CO2,D_Grp,INDEX(I_Top,4),D_An,S_An,D_Mois,3)) -> 0 | G26: =IF(INDEX(I_Top,5)="",0,SUMIFS(D_CO2,D_Grp,INDEX(I_Top,5),D_An,S_An,D_Mois,3)) -> 0 | H26: =IF(INDEX(I_Top,6)="",0,SUMIFS(D_CO2,D_Grp,INDEX(I_Top,6),D_An,S_An,D_Mois,3)) -> 0 | I26: =IF(INDEX(I_Top,7)="",0,SUMIFS(D_CO2,D_Grp,INDEX(I_Top,7),D_An,S_An,D_Mois,3)) -> 0 | J26: =IF(INDEX(I_Top,8)="",0,SUMIFS(D_CO2,D_Grp,INDEX(I_Top,8),D_An,S_An,D_Mois,3)) -> 0 | K26: =MAX(0,C9-SUM(C26:J26)) -> 0
B27: avr. | C27: =IF(INDEX(I_Top,1)="",0,SUMIFS(D_CO2,D_Grp,INDEX(I_Top,1),D_An,S_An,D_Mois,4)) -> 0 | D27: =IF(INDEX(I_Top,2)="",0,SUMIFS(D_CO2,D_Grp,INDEX(I_Top,2),D_An,S_An,D_Mois,4)) -> 0 | E27: =IF(INDEX(I_Top,3)="",0,SUMIFS(D_CO2,D_Grp,INDEX(I_Top,3),D_An,S_An,D_Mois,4)) -> 0 | F27: =IF(INDEX(I_Top,4)="",0,SUMIFS(D_CO2,D_Grp,INDEX(I_Top,4),D_An,S_An,D_Mois,4)) -> 0 | G27: =IF(INDEX(I_Top,5)="",0,SUMIFS(D_CO2,D_Grp,INDEX(I_Top,5),D_An,S_An,D_Mois,4)) -> 0 | H27: =IF(INDEX(I_Top,6)="",0,SUMIFS(D_CO2,D_Grp,INDEX(I_Top,6),D_An,S_An,D_Mois,4)) -> 0 | I27: =IF(INDEX(I_Top,7)="",0,SUMIFS(D_CO2,D_Grp,INDEX(I_Top,7),D_An,S_An,D_Mois,4)) -> 0 | J27: =IF(INDEX(I_Top,8)="",0,SUMIFS(D_CO2,D_Grp,INDEX(I_Top,8),D_An,S_An,D_Mois,4)) -> 0 | K27: =MAX(0,C10-SUM(C27:J27)) -> 0
B28: mai | C28: =IF(INDEX(I_Top,1)="",0,SUMIFS(D_CO2,D_Grp,INDEX(I_Top,1),D_An,S_An,D_Mois,5)) -> 0 | D28: =IF(INDEX(I_Top,2)="",0,SUMIFS(D_CO2,D_Grp,INDEX(I_Top,2),D_An,S_An,D_Mois,5)) -> 0 | E28: =IF(INDEX(I_Top,3)="",0,SUMIFS(D_CO2,D_Grp,INDEX(I_Top,3),D_An,S_An,D_Mois,5)) -> 0 | F28: =IF(INDEX(I_Top,4)="",0,SUMIFS(D_CO2,D_Grp,INDEX(I_Top,4),D_An,S_An,D_Mois,5)) -> 0 | G28: =IF(INDEX(I_Top,5)="",0,SUMIFS(D_CO2,D_Grp,INDEX(I_Top,5),D_An,S_An,D_Mois,5)) -> 0 | H28: =IF(INDEX(I_Top,6)="",0,SUMIFS(D_CO2,D_Grp,INDEX(I_Top,6),D_An,S_An,D_Mois,5)) -> 0 | I28: =IF(INDEX(I_Top,7)="",0,SUMIFS(D_CO2,D_Grp,INDEX(I_Top,7),D_An,S_An,D_Mois,5)) -> 0 | J28: =IF(INDEX(I_Top,8)="",0,SUMIFS(D_CO2,D_Grp,INDEX(I_Top,8),D_An,S_An,D_Mois,5)) -> 0 | K28: =MAX(0,C11-SUM(C28:J28)) -> 0
B29: juin | C29: =IF(INDEX(I_Top,1)="",0,SUMIFS(D_CO2,D_Grp,INDEX(I_Top,1),D_An,S_An,D_Mois,6)) -> 0 | D29: =IF(INDEX(I_Top,2)="",0,SUMIFS(D_CO2,D_Grp,INDEX(I_Top,2),D_An,S_An,D_Mois,6)) -> 0 | E29: =IF(INDEX(I_Top,3)="",0,SUMIFS(D_CO2,D_Grp,INDEX(I_Top,3),D_An,S_An,D_Mois,6)) -> 0 | F29: =IF(INDEX(I_Top,4)="",0,SUMIFS(D_CO2,D_Grp,INDEX(I_Top,4),D_An,S_An,D_Mois,6)) -> 0 | G29: =IF(INDEX(I_Top,5)="",0,SUMIFS(D_CO2,D_Grp,INDEX(I_Top,5),D_An,S_An,D_Mois,6)) -> 0 | H29: =IF(INDEX(I_Top,6)="",0,SUMIFS(D_CO2,D_Grp,INDEX(I_Top,6),D_An,S_An,D_Mois,6)) -> 0 | I29: =IF(INDEX(I_Top,7)="",0,SUMIFS(D_CO2,D_Grp,INDEX(I_Top,7),D_An,S_An,D_Mois,6)) -> 0 | J29: =IF(INDEX(I_Top,8)="",0,SUMIFS(D_CO2,D_Grp,INDEX(I_Top,8),D_An,S_An,D_Mois,6)) -> 0 | K29: =MAX(0,C12-SUM(C29:J29)) -> 0
B30: juil. | C30: =IF(INDEX(I_Top,1)="",0,SUMIFS(D_CO2,D_Grp,INDEX(I_Top,1),D_An,S_An,D_Mois,7)) -> 0 | D30: =IF(INDEX(I_Top,2)="",0,SUMIFS(D_CO2,D_Grp,INDEX(I_Top,2),D_An,S_An,D_Mois,7)) -> 0 | E30: =IF(INDEX(I_Top,3)="",0,SUMIFS(D_CO2,D_Grp,INDEX(I_Top,3),D_An,S_An,D_Mois,7)) -> 0 | F30: =IF(INDEX(I_Top,4)="",0,SUMIFS(D_CO2,D_Grp,INDEX(I_Top,4),D_An,S_An,D_Mois,7)) -> 0 | G30: =IF(INDEX(I_Top,5)="",0,SUMIFS(D_CO2,D_Grp,INDEX(I_Top,5),D_An,S_An,D_Mois,7)) -> 0 | H30: =IF(INDEX(I_Top,6)="",0,SUMIFS(D_CO2,D_Grp,INDEX(I_Top,6),D_An,S_An,D_Mois,7)) -> 0 | I30: =IF(INDEX(I_Top,7)="",0,SUMIFS(D_CO2,D_Grp,INDEX(I_Top,7),D_An,S_An,D_Mois,7)) -> 0 | J30: =IF(INDEX(I_Top,8)="",0,SUMIFS(D_CO2,D_Grp,INDEX(I_Top,8),D_An,S_An,D_Mois,7)) -> 0 | K30: =MAX(0,C13-SUM(C30:J30)) -> 0
B31: août | C31: =IF(INDEX(I_Top,1)="",0,SUMIFS(D_CO2,D_Grp,INDEX(I_Top,1),D_An,S_An,D_Mois,8)) -> 0 | D31: =IF(INDEX(I_Top,2)="",0,SUMIFS(D_CO2,D_Grp,INDEX(I_Top,2),D_An,S_An,D_Mois,8)) -> 0 | E31: =IF(INDEX(I_Top,3)="",0,SUMIFS(D_CO2,D_Grp,INDEX(I_Top,3),D_An,S_An,D_Mois,8)) -> 0 | F31: =IF(INDEX(I_Top,4)="",0,SUMIFS(D_CO2,D_Grp,INDEX(I_Top,4),D_An,S_An,D_Mois,8)) -> 0 | G31: =IF(INDEX(I_Top,5)="",0,SUMIFS(D_CO2,D_Grp,INDEX(I_Top,5),D_An,S_An,D_Mois,8)) -> 0 | H31: =IF(INDEX(I_Top,6)="",0,SUMIFS(D_CO2,D_Grp,INDEX(I_Top,6),D_An,S_An,D_Mois,8)) -> 0 | I31: =IF(INDEX(I_Top,7)="",0,SUMIFS(D_CO2,D_Grp,INDEX(I_Top,7),D_An,S_An,D_Mois,8)) -> 0 | J31: =IF(INDEX(I_Top,8)="",0,SUMIFS(D_CO2,D_Grp,INDEX(I_Top,8),D_An,S_An,D_Mois,8)) -> 0 | K31: =MAX(0,C14-SUM(C31:J31)) -> 0
B32: sept. | C32: =IF(INDEX(I_Top,1)="",0,SUMIFS(D_CO2,D_Grp,INDEX(I_Top,1),D_An,S_An,D_Mois,9)) -> 0 | D32: =IF(INDEX(I_Top,2)="",0,SUMIFS(D_CO2,D_Grp,INDEX(I_Top,2),D_An,S_An,D_Mois,9)) -> 0 | E32: =IF(INDEX(I_Top,3)="",0,SUMIFS(D_CO2,D_Grp,INDEX(I_Top,3),D_An,S_An,D_Mois,9)) -> 0 | F32: =IF(INDEX(I_Top,4)="",0,SUMIFS(D_CO2,D_Grp,INDEX(I_Top,4),D_An,S_An,D_Mois,9)) -> 0 | G32: =IF(INDEX(I_Top,5)="",0,SUMIFS(D_CO2,D_Grp,INDEX(I_Top,5),D_An,S_An,D_Mois,9)) -> 0 | H32: =IF(INDEX(I_Top,6)="",0,SUMIFS(D_CO2,D_Grp,INDEX(I_Top,6),D_An,S_An,D_Mois,9)) -> 0 | I32: =IF(INDEX(I_Top,7)="",0,SUMIFS(D_CO2,D_Grp,INDEX(I_Top,7),D_An,S_An,D_Mois,9)) -> 0 | J32: =IF(INDEX(I_Top,8)="",0,SUMIFS(D_CO2,D_Grp,INDEX(I_Top,8),D_An,S_An,D_Mois,9)) -> 0 | K32: =MAX(0,C15-SUM(C32:J32)) -> 0
B33: oct. | C33: =IF(INDEX(I_Top,1)="",0,SUMIFS(D_CO2,D_Grp,INDEX(I_Top,1),D_An,S_An,D_Mois,10)) -> 0 | D33: =IF(INDEX(I_Top,2)="",0,SUMIFS(D_CO2,D_Grp,INDEX(I_Top,2),D_An,S_An,D_Mois,10)) -> 0 | E33: =IF(INDEX(I_Top,3)="",0,SUMIFS(D_CO2,D_Grp,INDEX(I_Top,3),D_An,S_An,D_Mois,10)) -> 0 | F33: =IF(INDEX(I_Top,4)="",0,SUMIFS(D_CO2,D_Grp,INDEX(I_Top,4),D_An,S_An,D_Mois,10)) -> 0 | G33: =IF(INDEX(I_Top,5)="",0,SUMIFS(D_CO2,D_Grp,INDEX(I_Top,5),D_An,S_An,D_Mois,10)) -> 0 | H33: =IF(INDEX(I_Top,6)="",0,SUMIFS(D_CO2,D_Grp,INDEX(I_Top,6),D_An,S_An,D_Mois,10)) -> 0 | I33: =IF(INDEX(I_Top,7)="",0,SUMIFS(D_CO2,D_Grp,INDEX(I_Top,7),D_An,S_An,D_Mois,10)) -> 0 | J33: =IF(INDEX(I_Top,8)="",0,SUMIFS(D_CO2,D_Grp,INDEX(I_Top,8),D_An,S_An,D_Mois,10)) -> 0 | K33: =MAX(0,C16-SUM(C33:J33)) -> 0
B34: nov. | C34: =IF(INDEX(I_Top,1)="",0,SUMIFS(D_CO2,D_Grp,INDEX(I_Top,1),D_An,S_An,D_Mois,11)) -> 0 | D34: =IF(INDEX(I_Top,2)="",0,SUMIFS(D_CO2,D_Grp,INDEX(I_Top,2),D_An,S_An,D_Mois,11)) -> 0 | E34: =IF(INDEX(I_Top,3)="",0,SUMIFS(D_CO2,D_Grp,INDEX(I_Top,3),D_An,S_An,D_Mois,11)) -> 0 | F34: =IF(INDEX(I_Top,4)="",0,SUMIFS(D_CO2,D_Grp,INDEX(I_Top,4),D_An,S_An,D_Mois,11)) -> 0 | G34: =IF(INDEX(I_Top,5)="",0,SUMIFS(D_CO2,D_Grp,INDEX(I_Top,5),D_An,S_An,D_Mois,11)) -> 0 | H34: =IF(INDEX(I_Top,6)="",0,SUMIFS(D_CO2,D_Grp,INDEX(I_Top,6),D_An,S_An,D_Mois,11)) -> 0 | I34: =IF(INDEX(I_Top,7)="",0,SUMIFS(D_CO2,D_Grp,INDEX(I_Top,7),D_An,S_An,D_Mois,11)) -> 0 | J34: =IF(INDEX(I_Top,8)="",0,SUMIFS(D_CO2,D_Grp,INDEX(I_Top,8),D_An,S_An,D_Mois,11)) -> 0 | K34: =MAX(0,C17-SUM(C34:J34)) -> 0
B35: déc. | C35: =IF(INDEX(I_Top,1)="",0,SUMIFS(D_CO2,D_Grp,INDEX(I_Top,1),D_An,S_An,D_Mois,12)) -> 0 | D35: =IF(INDEX(I_Top,2)="",0,SUMIFS(D_CO2,D_Grp,INDEX(I_Top,2),D_An,S_An,D_Mois,12)) -> 0 | E35: =IF(INDEX(I_Top,3)="",0,SUMIFS(D_CO2,D_Grp,INDEX(I_Top,3),D_An,S_An,D_Mois,12)) -> 0 | F35: =IF(INDEX(I_Top,4)="",0,SUMIFS(D_CO2,D_Grp,INDEX(I_Top,4),D_An,S_An,D_Mois,12)) -> 0 | G35: =IF(INDEX(I_Top,5)="",0,SUMIFS(D_CO2,D_Grp,INDEX(I_Top,5),D_An,S_An,D_Mois,12)) -> 0 | H35: =IF(INDEX(I_Top,6)="",0,SUMIFS(D_CO2,D_Grp,INDEX(I_Top,6),D_An,S_An,D_Mois,12)) -> 0 | I35: =IF(INDEX(I_Top,7)="",0,SUMIFS(D_CO2,D_Grp,INDEX(I_Top,7),D_An,S_An,D_Mois,12)) -> 0 | J35: =IF(INDEX(I_Top,8)="",0,SUMIFS(D_CO2,D_Grp,INDEX(I_Top,8),D_An,S_An,D_Mois,12)) -> 0 | K35: =MAX(0,C18-SUM(C35:J35)) -> 0
B38: Classement des modèles (année affichée)
B39: Rang | C39: Modèle | D39: kgCO₂e | E39: Part | F39: Énergie | G39: Tokens éq. output | H39: Coût brut | I39: gCO₂e par $ | J39: FE retenu (kgCO₂e/token) | K39: Source du FE
B40: =IF(C40="","",1) | C40: =IF(INDEX(I_CO2,L40)>0,INDEX(I_Nom,L40),"") | D40: =IF(C40="","",INDEX(I_CO2,L40)) | E40: =IF(C40="","",D40/S_YTD) | F40: =IF(C40="","",INDEX(I_kWh,L40)) | G40: =IF(C40="","",INDEX(I_TO,L40)) | H40: =IF(C40="","",INDEX(I_Brut,L40)) | I40: =IF(C40="","",IF(H40>0,D40*1000/H40,"")) | J40: =IF(C40="","",INDEX(M_FE,L40)) | K40: =IF(C40="","",INDEX(M_Src,L40)) | L40: =MATCH(LARGE(I_Key,1),I_Key,0) -> 1
B41: =IF(C41="","",2) | C41: =IF(INDEX(I_CO2,L41)>0,INDEX(I_Nom,L41),"") | D41: =IF(C41="","",INDEX(I_CO2,L41)) | E41: =IF(C41="","",D41/S_YTD) | F41: =IF(C41="","",INDEX(I_kWh,L41)) | G41: =IF(C41="","",INDEX(I_TO,L41)) | H41: =IF(C41="","",INDEX(I_Brut,L41)) | I41: =IF(C41="","",IF(H41>0,D41*1000/H41,"")) | J41: =IF(C41="","",INDEX(M_FE,L41)) | K41: =IF(C41="","",INDEX(M_Src,L41)) | L41: =MATCH(LARGE(I_Key,2),I_Key,0) -> 2
B42: =IF(C42="","",3) | C42: =IF(INDEX(I_CO2,L42)>0,INDEX(I_Nom,L42),"") | D42: =IF(C42="","",INDEX(I_CO2,L42)) | E42: =IF(C42="","",D42/S_YTD) | F42: =IF(C42="","",INDEX(I_kWh,L42)) | G42: =IF(C42="","",INDEX(I_TO,L42)) | H42: =IF(C42="","",INDEX(I_Brut,L42)) | I42: =IF(C42="","",IF(H42>0,D42*1000/H42,"")) | J42: =IF(C42="","",INDEX(M_FE,L42)) | K42: =IF(C42="","",INDEX(M_Src,L42)) | L42: =MATCH(LARGE(I_Key,3),I_Key,0) -> 3
B43: =IF(C43="","",4) | C43: =IF(INDEX(I_CO2,L43)>0,INDEX(I_Nom,L43),"") | D43: =IF(C43="","",INDEX(I_CO2,L43)) | E43: =IF(C43="","",D43/S_YTD) | F43: =IF(C43="","",INDEX(I_kWh,L43)) | G43: =IF(C43="","",INDEX(I_TO,L43)) | H43: =IF(C43="","",INDEX(I_Brut,L43)) | I43: =IF(C43="","",IF(H43>0,D43*1000/H43,"")) | J43: =IF(C43="","",INDEX(M_FE,L43)) | K43: =IF(C43="","",INDEX(M_Src,L43)) | L43: =MATCH(LARGE(I_Key,4),I_Key,0) -> 4
B44: =IF(C44="","",5) | C44: =IF(INDEX(I_CO2,L44)>0,INDEX(I_Nom,L44),"") | D44: =IF(C44="","",INDEX(I_CO2,L44)) | E44: =IF(C44="","",D44/S_YTD) | F44: =IF(C44="","",INDEX(I_kWh,L44)) | G44: =IF(C44="","",INDEX(I_TO,L44)) | H44: =IF(C44="","",INDEX(I_Brut,L44)) | I44: =IF(C44="","",IF(H44>0,D44*1000/H44,"")) | J44: =IF(C44="","",INDEX(M_FE,L44)) | K44: =IF(C44="","",INDEX(M_Src,L44)) | L44: =MATCH(LARGE(I_Key,5),I_Key,0) -> 5
B45: =IF(C45="","",6) | C45: =IF(INDEX(I_CO2,L45)>0,INDEX(I_Nom,L45),"") | D45: =IF(C45="","",INDEX(I_CO2,L45)) | E45: =IF(C45="","",D45/S_YTD) | F45: =IF(C45="","",INDEX(I_kWh,L45)) | G45: =IF(C45="","",INDEX(I_TO,L45)) | H45: =IF(C45="","",INDEX(I_Brut,L45)) | I45: =IF(C45="","",IF(H45>0,D45*1000/H45,"")) | J45: =IF(C45="","",INDEX(M_FE,L45)) | K45: =IF(C45="","",INDEX(M_Src,L45)) | L45: =MATCH(LARGE(I_Key,6),I_Key,0) -> 6
...

Sheet Calcul
B2: Calcul
B3: Formules, paramètres globaux et paramètres par modèle. Les cellules jaunes sont modifiables ; tout le classeur se recalcule.
B5: Réglages généraux | G5: Familles : convention par défaut (API du fournisseur)
B6: Source des facteurs d'émission | C6: Table fournie | D6: « Table fournie » = votre table kgCO₂e/token (23/10/2026). Les modèles absents de la table passent par le Calculateur de Boris. | G6: Famille | H6: Convention | I6: Source
B7: Mix électrique (Calculateur de Boris) | C7: France (2020, EEA) | D7: Sert au calcul des modèles absents de la table, et à la vue de sensibilité C6. | G7: Anthropic | H7: Exclusive | I7: Doc Anthropic : total = cache read + cache creation + input
B8: Mix personnalisé (gCO₂e/kWh) | C8: 300 | D8: Utilisé seulement si le mix choisi est « Personnalisé ». | G8: OpenAI ≥ GPT-5.6 | H8: Inclusive | I8: Doc OpenAI : input ordinaire = input − cached − write
B9: Mix retenu (gCO₂e/kWh) | C9: =IF(P_MixNom="Personnalisé",P_MixPerso,INDEX(L_MixVal,MATCH(P_MixNom,L_MixNom,0))) -> 51.1 | D9: =INDEX(L_MixSrc,MATCH(P_MixNom,L_MixNom,0)) -> EEA, défaut du Calculateur de Boris | G9: OpenAI < GPT-5.6 | H9: Inclusive | I9: Doc OpenAI : pas d'écriture facturée (ε sans objet)
B10: Inclure la fabrication (scope 3) | C10: Oui | D10: Le Calculateur de Boris ajoute la fabrication du matériel par token. Votre méthode l'exclut : mettre « Non » pour s'y conformer. | G10: Google Gemini | H10: Inclusive | I10: Doc Gemini : promptTokenCount inclut le cache
B11: Fourchette d'incertitude basse (×) | C11: 0.5 | D11: Multiplicateur appliqué au résultat central pour la borne basse. | G11: xAI Grok | H11: Inclusive | I11: Doc xAI : le total du prompt compte le cache
B12: Fourchette d'incertitude haute (×) | C12: 2 | D12: Multiplicateur appliqué au résultat central pour la borne haute. | G12: Moonshot Kimi | H12: Inclusive | I12: Doc Fireworks : cache inclus dans le total du prompt
B13: Projection : fenêtre (jours) | C13: 28 | D13: Rythme quotidien moyen des N derniers jours de données, prolongé jusqu'au 31 décembre. | G13: Microsoft MAI | H13: Inclusive | I13: Aucune source trouvée : inclusive par défaut
B14: Projection : ajustement | C14: 0 | D14: Hausse ou baisse appliquée au rythme projeté (ex. +10 % si le déploiement s'élargit). | G14: Hors grille | H14: Inclusive | I14: Modèle absent de la grille : inclusive par défaut
G15: Ordre d'application : convention forcée, sinon C2 (cache > input sur une ligne : exclusive), sinon C3 (rapprochement des coûts de la famille), sinon cette valeur.
B16: Formules (par ligne de l'export)
B17: Input frais (tokens) | C17: F = max(0, I − δ·CR − ε·CW)
B18: Tokens équivalent output | C18: T_O = F·s_I + CR·s_CR + CW·s_CW + O
B19: Énergie (kWh) | C19: E = T_O × e_O × PUE / 1000
B20: Empreinte (kgCO₂e) | C20: CO₂e = T_O × FE_token
B21: FE_token calculé (Calculateur de Boris) | C21: FE = e_O × PUE × FE_mix / 10⁶ + fab
B23: I, O, CR, CW : colonnes input, output, cache_read, cache_write. δ, ε : convention de l'input (1 = l'input contient déjà le cache). s_I, s_CR, s_CW : prix rapportés au prix de l'output. Les formules sont dans les colonnes bleues de l'onglet Données.
B27: Paramètres par modèle
B28: Grille GitHub du 20/10/2026 ($ par million de tokens). Pour un nouveau modèle, remplissez une ligne vide en bas de la table (au minimum Modèle, prix et e_O). Les noms « Auto: X » utilisent la ligne de X. « (Autre modèle) » sert aux modèles inconnus.
B29: Modèle | C29: Famille | D29: Convention forcée | E29: Convention appliquée | F29: Origine | G29: δ | H29: ε | I29: P_I | J29: P_CR | K29: P_CW | L29: P_O | M29: Tarif valable avant le | N29: s_I | O29: s_CR | P29: s_CW | Q29: Scénario EcoLogits | R29: e_O (Wh/token) | S29: PUE | T29: fab (kgCO₂e/token) | U29: FE table (kgCO₂e/token) | V29: S/H | W29: FE forcé (kgCO₂e/token) | X29: FE calculé (kgCO₂e/token) | Y29: FE retenu (kgCO₂e/token) | Z29: Source du FE
B30: GPT-5.3-Codex | C30: OpenAI < GPT-5.6 | E30: =IF(B30="","",IF(D30<>"",D30,IF('Contrôles'!$J$62>0,"Exclusive",IF('Contrôles'!$U$62<>"",'Contrôles'!$U$62,IFERROR(INDEX(F_Conv,MATCH(C30,F_Fam,0)),"Inclusive"))))) -> Inclusive | F30: =IF(B30="","",IF(D30<>"","Forcée",IF('Contrôles'!$J$62>0,"C2",IF('Contrôles'!$U$62<>"","C3","Défaut API")))) -> Défaut API | G30: =IF(B30="","",IF(E30="Exclusive",0,1)) -> 1 | H30: =IF(B30="","",IF(E30="Inclusive",1,0)) -> 1 | I30: 1.75 | J30: 0.175 | L30: 14 | N30: =IF(B30="","",IF(N(L30)>0,I30/L30,0.2)) -> 0.125 | O30: =IF(B30="","",IF(N(L30)>0,J30/L30,0.02)) -> 0.0125 | P30: =IF(B30="","",IF(N(L30)>0,IF(K30="",I30,K30)/L30,0.25)) -> 0.125 | Q30: gpt-5.3-codex | R30: 0.0020268642 | S30: 1.2 | T30: 5.124195e-08 | U30: 5.9e-07 | V30: H | X30: =IF(B30="","",R30*S30*P_Mix/1000000+IF(P_Fab="Oui",T30,0)) -> 1.7552926e-07 | Y30: =IF(B30="","",IF(W30<>"",W30,IF(AND(P_Source="Table fournie",U30<>""),U30,X30))) -> 5.9e-07 | Z30: =IF(B30="","",IF(W30<>"","Forcé",IF(AND(P_Source="Table fournie",U30<>""),IF(V30="H","Table (hypothèse)","Table (sourcé)"),"Calculateur de Boris"))) -> Table (hypothèse)
B31: GPT-5.4 nano | C31: OpenAI < GPT-5.6 | E31: =IF(B31="","",IF(D31<>"",D31,IF('Contrôles'!$J$63>0,"Exclusive",IF('Contrôles'!$U$63<>"",'Contrôles'!$U$63,IFERROR(INDEX(F_Conv,MATCH(C31,F_Fam,0)),"Inclusive"))))) -> Inclusive | F31: =IF(B31="","",IF(D31<>"","Forcée",IF('Contrôles'!$J$63>0,"C2",IF('Contrôles'!$U$63<>"","C3","Défaut API")))) -> Défaut API | G31: =IF(B31="","",IF(E31="Exclusive",0,1)) -> 1 | H31: =IF(B31="","",IF(E31="Inclusive",1,0)) -> 1 | I31: 0.2 | J31: 0.02 | L31: 1.25 | N31: =IF(B31="","",IF(N(L31)>0,I31/L31,0.2)) -> 0.16 | O31: =IF(B31="","",IF(N(L31)>0,J31/L31,0.02)) -> 0.016 | P31: =IF(B31="","",IF(N(L31)>0,IF(K31="",I31,K31)/L31,0.25)) -> 0.16 | Q31: gpt-5-nano (proxy) | R31: 5.6971481e-05 | S31: 1.2 | T31: 1.756778e-09 | U31: 1.659e-08 | V31: H | X31: =IF(B31="","",R31*S31*P_Mix/1000000+IF(P_Fab="Oui",T31,0)) -> 5.2502692e-09 | Y31: =IF(B31="","",IF(W31<>"",W31,IF(AND(P_Source="Table fournie",U31<>""),U31,X31))) -> 1.659e-08 | Z31: =IF(B31="","",IF(W31<>"","Forcé",IF(AND(P_Source="Table fournie",U31<>""),IF(V31="H","Table (hypothèse)","Table (sourcé)"),"Calculateur de Boris"))) -> Table (hypothèse)
B32: GPT-5.6 Luna | C32: OpenAI ≥ GPT-5.6 | E32: =IF(B32="","",IF(D32<>"",D32,IF('Contrôles'!$J$64>0,"Exclusive",IF('Contrôles'!$U$64<>"",'Contrôles'!$U$64,IFERROR(INDEX(F_Conv,MATCH(C32,F_Fam,0)),"Inclusive"))))) -> Inclusive | F32: =IF(B32="","",IF(D32<>"","Forcée",IF('Contrôles'!$J$64>0,"C2",IF('Contrôles'!$U$64<>"","C3","Défaut API")))) -> Défaut API | G32: =IF(B32="","",IF(E32="Exclusive",0,1)) -> 1 | H32: =IF(B32="","",IF(E32="Inclusive",1,0)) -> 1 | I32: 0.2 | J32: 0.02 | K32: 0.25 | L32: 1.2 | N32: =IF(B32="","",IF(N(L32)>0,I32/L32,0.2)) -> 0.16666667 | O32: =IF(B32="","",IF(N(L32)>0,J32/L32,0.02)) -> 0.016666667 | P32: =IF(B32="","",IF(N(L32)>0,IF(K32="",I32,K32)/L32,0.25)) -> 0.20833333 | Q32: gpt-5-mini (proxy) | R32: 0.00037684316 | S32: 1.2 | T32: 1.229372e-08 | U32: 1e-08 | V32: S | X32: =IF(B32="","",R32*S32*P_Mix/1000000+IF(P_Fab="Oui",T32,0)) -> 3.5401743e-08 | Y32: =IF(B32="","",IF(W32<>"",W32,IF(AND(P_Source="Table fournie",U32<>""),U32,X32))) -> 1e-08 | Z32: =IF(B32="","",IF(W32<>"","Forcé",IF(AND(P_Source="Table fournie",U32<>""),IF(V32="H","Table (hypothèse)","Table (sourcé)"),"Calculateur de Boris"))) -> Table (sourcé)
B33: GPT-5.6 Terra | C33: OpenAI ≥ GPT-5.6 | E33: =IF(B33="","",IF(D33<>"",D33,IF('Contrôles'!$J$65>0,"Exclusive",IF('Contrôles'!$U$65<>"",'Contrôles'!$U$65,IFERROR(INDEX(F_Conv,MATCH(C33,F_Fam,0)),"Inclusive"))))) -> Inclusive | F33: =IF(B33="","",IF(D33<>"","Forcée",IF('Contrôles'!$J$65>0,"C2",IF('Contrôles'!$U$65<>"","C3","Défaut API")))) -> Défaut API | G33: =IF(B33="","",IF(E33="Exclusive",0,1)) -> 1 | H33: =IF(B33="","",IF(E33="Inclusive",1,0)) -> 1 | I33: 2 | J33: 0.2 | K33: 2.5 | L33: 12 | N33: =IF(B33="","",IF(N(L33)>0,I33/L33,0.2)) -> 0.16666667 | O33: =IF(B33="","",IF(N(L33)>0,J33/L33,0.02)) -> 0.016666667 | P33: =IF(B33="","",IF(N(L33)>0,IF(K33="",I33,K33)/L33,0.25)) -> 0.20833333 | Q33: gpt-5.4 (proxy) | R33: 0.0017884687 | S33: 1.2 | T33: 5.090409e-08 | U33: 1e-07 | V33: S | X33: =IF(B33="","",R33*S33*P_Mix/1000000+IF(P_Fab="Oui",T33,0)) -> 1.6057299e-07 | Y33: =IF(B33="","",IF(W33<>"",W33,IF(AND(P_Source="Table fournie",U33<>""),U33,X33))) -> 1e-07 | Z33: =IF(B33="","",IF(W33<>"","Forcé",IF(AND(P_Source="Table fournie",U33<>""),IF(V33="H","Table (hypothèse)","Table (sourcé)"),"Calculateur de Boris"))) -> Table (sourcé)
B34: GPT-5.6 Sol | C34: OpenAI ≥ GPT-5.6 | E34: =IF(B34="","",IF(D34<>"",D34,IF('Contrôles'!$J$66>0,"Exclusive",IF('Contrôles'!$U$66<>"",'Contrôles'!$U$66,IFERROR(INDEX(F_Conv,MATCH(C34,F_Fam,0)),"Inclusive"))))) -> Inclusive | F34: =IF(B34="","",IF(D34<>"","Forcée",IF('Contrôles'!$J$66>0,"C2",IF('Contrôles'!$U$66<>"","C3","Défaut API")))) -> Défaut API | G34: =IF(B34="","",IF(E34="Exclusive",0,1)) -> 1 | H34: =IF(B34="","",IF(E34="Inclusive",1,0)) -> 1 | I34: 4 | J34: 0.4 | K34: 5 | L34: 20 | N34: =IF(B34="","",IF(N(L34)>0,I34/L34,0.2)) -> 0.2 | O34: =IF(B34="","",IF(N(L34)>0,J34/L34,0.02)) -> 0.02 | P34: =IF(B34="","",IF(N(L34)>0,IF(K34="",I34,K34)/L34,0.25)) -> 0.25 | Q34: gpt-5.5 (proxy) | R34: 0.0054568626 | S34: 1.2 | T34: 1.146602e-07 | U34: 5.9e-07 | V34: S | X34: =IF(B34="","",R34*S34*P_Mix/1000000+IF(P_Fab="Oui",T34,0)) -> 4.4927501e-07 | Y34: =IF(B34="","",IF(W34<>"",W34,IF(AND(P_Source="Table fournie",U34<>""),U34,X34))) -> 5.9e-07 | Z34: =IF(B34="","",IF(W34<>"","Forcé",IF(AND(P_Source="Table fournie",U34<>""),IF(V34="H","Table (hypothèse)","Table (sourcé)"),"Calculateur de Boris"))) -> Table (sourcé)
B35: GPT-6 Luna | C35: OpenAI ≥ GPT-5.6 | E35: =IF(B35="","",IF(D35<>"",D35,IF('Contrôles'!$J$67>0,"Exclusive",IF('Contrôles'!$U$67<>"",'Contrôles'!$U$67,IFERROR(INDEX(F_Conv,MATCH(C35,F_Fam,0)),"Inclusive"))))) -> Inclusive | F35: =IF(B35="","",IF(D35<>"","Forcée",IF('Contrôles'!$J$67>0,"C2",IF('Contrôles'!$U$67<>"","C3","Défaut API")))) -> Défaut API | G35: =IF(B35="","",IF(E35="Exclusive",0,1)) -> 1 | H35: =IF(B35="","",IF(E35="Inclusive",1,0)) -> 1 | I35: 0.1 | J35: 0.01 | K35: 0.125 | L35: 0.5 | N35: =IF(B35="","",IF(N(L35)>0,I35/L35,0.2)) -> 0.2 | O35: =IF(B35="","",IF(N(L35)>0,J35/L35,0.02)) -> 0.02 | P35: =IF(B35="","",IF(N(L35)>0,IF(K35="",I35,K35)/L35,0.25)) -> 0.25 | Q35: gpt-5-nano (proxy) | R35: 5.6971481e-05 | S35: 1.2 | T35: 1.756778e-09 | U35: 1e-08 | V35: S | X35: =IF(B35="","",R35*S35*P_Mix/1000000+IF(P_Fab="Oui",T35,0)) -> 5.2502692e-09 | Y35: =IF(B35="","",IF(W35<>"",W35,IF(AND(P_Source="Table fournie",U35<>""),U35,X35))) -> 1e-08 | Z35: =IF(B35="","",IF(W35<>"","Forcé",IF(AND(P_Source="Table fournie",U35<>""),IF(V35="H","Table (hypothèse)","Table (sourcé)"),"Calculateur de Boris"))) -> Table (sourcé)
B36: GPT-6 Sol | C36: OpenAI ≥ GPT-5.6 | E36: =IF(B36="","",IF(D36<>"",D36,IF('Contrôles'!$J$68>0,"Exclusive",IF('Contrôles'!$U$68<>"",'Contrôles'!$U$68,IFERROR(INDEX(F_Conv,MATCH(C36,F_Fam,0)),"Inclusive"))))) -> Inclusive | F36: =IF(B36="","",IF(D36<>"","Forcée",IF('Contrôles'!$J$68>0,"C2",IF('Contrôles'!$U$68<>"","C3","Défaut API")))) -> Défaut API | G36: =IF(B36="","",IF(E36="Exclusive",0,1)) -> 1 | H36: =IF(B36="","",IF(E36="Inclusive",1,0)) -> 1 | I36: 2 | J36: 0.2 | K36: 2.5 | L36: 10 | N36: =IF(B36="","",IF(N(L36)>0,I36/L36,0.2)) -> 0.2 | O36: =IF(B36="","",IF(N(L36)>0,J36/L36,0.02)) -> 0.02 | P36: =IF(B36="","",IF(N(L36)>0,IF(K36="",I36,K36)/L36,0.25)) -> 0.25 | Q36: gpt-5.4 (proxy) | R36: 0.0017884687 | S36: 1.2 | T36: 5.090409e-08 | U36: 1e-08 | V36: H | X36: =IF(B36="","",R36*S36*P_Mix/1000000+IF(P_Fab="Oui",T36,0)) -> 1.6057299e-07 | Y36: =IF(B36="","",IF(W36<>"",W36,IF(AND(P_Source="Table fournie",U36<>""),U36,X36))) -> 1e-08 | Z36: =IF(B36="","",IF(W36<>"","Forcé",IF(AND(P_Source="Table fournie",U36<>""),IF(V36="H","Table (hypothèse)","Table (sourcé)"),"Calculateur de Boris"))) -> Table (hypothèse)
B37: GPT-6 Astra | C37: OpenAI ≥ GPT-5.6 | E37: =IF(B37="","",IF(D37<>"",D37,IF('Contrôles'!$J$69>0,"Exclusive",IF('Contrôles'!$U$69<>"",'Contrôles'!$U$69,IFERROR(INDEX(F_Conv,MATCH(C37,F_Fam,0)),"Inclusive"))))) -> Inclusive | F37: =IF(B37="","",IF(D37<>"","Forcée",IF('Contrôles'!$J$69>0,"C2",IF('Contrôles'!$U$69<>"","C3","Défaut API")))) -> Défaut API | G37: =IF(B37="","",IF(E37="Exclusive",0,1)) -> 1 | H37: =IF(B37="","",IF(E37="Inclusive",1,0)) -> 1 | I37: 10 | J37: 1 | K37: 12.5 | L37: 50 | N37: =IF(B37="","",IF(N(L37)>0,I37/L37,0.2)) -> 0.2 | O37: =IF(B37="","",IF(N(L37)>0,J37/L37,0.02)) -> 0.02 | P37: =IF(B37="","",IF(N(L37)>0,IF(K37="",I37,K37)/L37,0.25)) -> 0.25 | Q37: gpt-5.5 (proxy) | R37: 0.0054568626 | S37: 1.2 | T37: 1.146602e-07 | U37: 1e-08 | V37: H | X37: =IF(B37="","",R37*S37*P_Mix/1000000+IF(P_Fab="Oui",T37,0)) -> 4.4927501e-07 | Y37: =IF(B37="","",IF(W37<>"",W37,IF(AND(P_Source="Table fournie",U37<>""),U37,X37))) -> 1e-08 | Z37: =IF(B37="","",IF(W37<>"","Forcé",IF(AND(P_Source="Table fournie",U37<>""),IF(V37="H","Table (hypothèse)","Table (sourcé)"),"Calculateur de Boris"))) -> Table (hypothèse)
B38: GPT-6.1 Sol | C38: OpenAI ≥ GPT-5.6 | E38: =IF(B38="","",IF(D38<>"",D38,IF('Contrôles'!$J$70>0,"Exclusive",IF('Contrôles'!$U$70<>"",'Contrôles'!$U$70,IFERROR(INDEX(F_Conv,MATCH(C38,F_Fam,0)),"Inclusive"))))) -> Inclusive | F38: =IF(B38="","",IF(D38<>"","Forcée",IF('Contrôles'!$J$70>0,"C2",IF('Contrôles'!$U$70<>"","C3","Défaut API")))) -> Défaut API | G38: =IF(B38="","",IF(E38="Exclusive",0,1)) -> 1 | H38: =IF(B38="","",IF(E38="Inclusive",1,0)) -> 1 | I38: 2 | J38: 0.1 | K38: 2.5 | L38: 10 | N38: =IF(B38="","",IF(N(L38)>0,I38/L38,0.2)) -> 0.2 | O38: =IF(B38="","",IF(N(L38)>0,J38/L38,0.02)) -> 0.01 | P38: =IF(B38="","",IF(N(L38)>0,IF(K38="",I38,K38)/L38,0.25)) -> 0.25 | Q38: gpt-5.4 (proxy) | R38: 0.0017884687 | S38: 1.2 | T38: 5.090409e-08 | U38: 1e-08 | V38: H | X38: =IF(B38="","",R38*S38*P_Mix/1000000+IF(P_Fab="Oui",T38,0)) -> 1.6057299e-07 | Y38: =IF(B38="","",IF(W38<>"",W38,IF(AND(P_Source="Table fournie",U38<>""),U38,X38))) -> 1e-08 | Z38: =IF(B38="","",IF(W38<>"","Forcé",IF(AND(P_Source="Table fournie",U38<>""),IF(V38="H","Table (hypothèse)","Table (sourcé)"),"Calculateur de Boris"))) -> Table (hypothèse)
B39: GPT-5 mini | C39: OpenAI < GPT-5.6 | E39: =IF(B39="","",IF(D39<>"",D39,IF('Contrôles'!$J$71>0,"Exclusive",IF('Contrôles'!$U$71<>"",'Contrôles'!$U$71,IFERROR(INDEX(F_Conv,MATCH(C39,F_Fam,0)),"Inclusive"))))) -> Inclusive | F39: =IF(B39="","",IF(D39<>"","Forcée",IF('Contrôles'!$J$71>0,"C2",IF('Contrôles'!$U$71<>"","C3","Défaut API")))) -> Défaut API | G39: =IF(B39="","",IF(E39="Exclusive",0,1)) -> 1 | H39: =IF(B39="","",IF(E39="Inclusive",1,0)) -> 1 | I39: 0.25 | J39: 0.025 | L39: 2 | N39: =IF(B39="","",IF(N(L39)>0,I39/L39,0.2)) -> 0.125 | O39: =IF(B39="","",IF(N(L39)>0,J39/L39,0.02)) -> 0.0125 | P39: =IF(B39="","",IF(N(L39)>0,IF(K39="",I39,K39)/L39,0.25)) -> 0.125 | Q39: gpt-5-mini | R39: 0.00037684316 | S39: 1.2 | T39: 1.229372e-08 | U39: 1.1039e-07 | V39: S | X39: =IF(B39="","",R39*S39*P_Mix/1000000+IF(P_Fab="Oui",T39,0)) -> 3.5401743e-08 | Y39: =IF(B39="","",IF(W39<>"",W39,IF(AND(P_Source="Table fournie",U39<>""),U39,X39))) -> 1.1039e-07 | Z39: =IF(B39="","",IF(W39<>"","Forcé",IF(AND(P_Source="Table fournie",U39<>""),IF(V39="H","Table (hypothèse)","Table (sourcé)"),"Calculateur de Boris"))) -> Table (sourcé)
B40: GPT-5.4 mini | C40: OpenAI < GPT-5.6 | E40: =IF(B40="","",IF(D40<>"",D40,IF('Contrôles'!$J$72>0,"Exclusive",IF('Contrôles'!$U$72<>"",'Contrôles'!$U$72,IFERROR(INDEX(F_Conv,MATCH(C40,F_Fam,0)),"Inclusive"))))) -> Inclusive | F40: =IF(B40="","",IF(D40<>"","Forcée",IF('Contrôles'!$J$72>0,"C2",IF('Contrôles'!$U$72<>"","C3","Défaut API")))) -> Défaut API | G40: =IF(B40="","",IF(E40="Exclusive",0,1)) -> 1 | H40: =IF(B40="","",IF(E40="Inclusive",1,0)) -> 1 | I40: 0.75 | J40: 0.075 | L40: 4.5 | N40: =IF(B40="","",IF(N(L40)>0,I40/L40,0.2)) -> 0.16666667 | O40: =IF(B40="","",IF(N(L40)>0,J40/L40,0.02)) -> 0.016666667 | P40: =IF(B40="","",IF(N(L40)>0,IF(K40="",I40,K40)/L40,0.25)) -> 0.16666667 | Q40: gpt-5-mini (proxy) | R40: 0.00037684316 | S40: 1.2 | T40: 1.229372e-08 | U40: 8.028e-08 | V40: H | X40: =IF(B40="","",R40*S40*P_Mix/1000000+IF(P_Fab="Oui",T40,0)) -> 3.5401743e-08 | Y40: =IF(B40="","",IF(W40<>"",W40,IF(AND(P_Source="Table fournie",U40<>""),U40,X40))) -> 8.028e-08 | Z40: =IF(B40="","",IF(W40<>"","Forcé",IF(AND(P_Source="Table fournie",U40<>""),IF(V40="H","Table (hypothèse)","Table (sourcé)"),"Calculateur de Boris"))) -> Table (hypothèse)
B41: GPT-5.4 | C41: OpenAI < GPT-5.6 | E41: =IF(B41="","",IF(D41<>"",D41,IF('Contrôles'!$J$73>0,"Exclusive",IF('Contrôles'!$U$73<>"",'Contrôles'!$U$73,IFERROR(INDEX(F_Conv,MATCH(C41,F_Fam,0)),"Inclusive"))))) -> Inclusive | F41: =IF(B41="","",IF(D41<>"","Forcée",IF('Contrôles'!$J$73>0,"C2",IF('Contrôles'!$U$73<>"","C3","Défaut API")))) -> Défaut API | G41: =IF(B41="","",IF(E41="Exclusive",0,1)) -> 1 | H41: =IF(B41="","",IF(E41="Inclusive",1,0)) -> 1 | I41: 2.5 | J41: 0.25 | L41: 15 | N41: =IF(B41="","",IF(N(L41)>0,I41/L41,0.2)) -> 0.16666667 | O41: =IF(B41="","",IF(N(L41)>0,J41/L41,0.02)) -> 0.016666667 | P41: =IF(B41="","",IF(N(L41)>0,IF(K41="",I41,K41)/L41,0.25)) -> 0.16666667 | Q41: gpt-5.4 | R41: 0.0017884687 | S41: 1.2 | T41: 5.090409e-08 | U41: 4.7e-07 | V41: S | X41: =IF(B41="","",R41*S41*P_Mix/1000000+IF(P_Fab="Oui",T41,0)) -> 1.6057299e-07 | Y41: =IF(B41="","",IF(W41<>"",W41,IF(AND(P_Source="Table fournie",U41<>""),U41,X41))) -> 4.7e-07 | Z41: =IF(B41="","",IF(W41<>"","Forcé",IF(AND(P_Source="Table fournie",U41<>""),IF(V41="H","Table (hypothèse)","Table (sourcé)"),"Calculateur de Boris"))) -> Table (sourcé)
B42: GPT-5.5 | C42: OpenAI < GPT-5.6 | E42: =IF(B42="","",IF(D42<>"",D42,IF('Contrôles'!$J$74>0,"Exclusive",IF('Contrôles'!$U$74<>"",'Contrôles'!$U$74,IFERROR(INDEX(F_Conv,MATCH(C42,F_Fam,0)),"Inclusive"))))) -> Inclusive | F42: =IF(B42="","",IF(D42<>"","Forcée",IF('Contrôles'!$J$74>0,"C2",IF('Contrôles'!$U$74<>"","C3","Défaut API")))) -> Défaut API | G42: =IF(B42="","",IF(E42="Exclusive",0,1)) -> 1 | H42: =IF(B42="","",IF(E42="Inclusive",1,0)) -> 1 | I42: 5 | J42: 0.5 | L42: 30 | N42: =IF(B42="","",IF(N(L42)>0,I42/L42,0.2)) -> 0.16666667 | O42: =IF(B42="","",IF(N(L42)>0,J42/L42,0.02)) -> 0.016666667 | P42: =IF(B42="","",IF(N(L42)>0,IF(K42="",I42,K42)/L42,0.25)) -> 0.16666667 | Q42: gpt-5.5 | R42: 0.0054568626 | S42: 1.2 | T42: 1.146602e-07 | U42: 1.42e-06 | V42: S | X42: =IF(B42="","",R42*S42*P_Mix/1000000+IF(P_Fab="Oui",T42,0)) -> 4.4927501e-07 | Y42: =IF(B42="","",IF(W42<>"",W42,IF(AND(P_Source="Table fournie",U42<>""),U42,X42))) -> 1.42e-06 | Z42: =IF(B42="","",IF(W42<>"","Forcé",IF(AND(P_Source="Table fournie",U42<>""),IF(V42="H","Table (hypothèse)","Table (sourcé)"),"Calculateur de Boris"))) -> Table (sourcé)
B43: Claude Haiku 4.5 | C43: Anthropic | E43: =IF(B43="","",IF(D43<>"",D43,IF('Contrôles'!$J$75>0,"Exclusive",IF('Contrôles'!$U$75<>"",'Contrôles'!$U$75,IFERROR(INDEX(F_Conv,MATCH(C43,F_Fam,0)),"Inclusive"))))) -> Exclusive | F43: =IF(B43="","",IF(D43<>"","Forcée",IF('Contrôles'!$J$75>0,"C2",IF('Contrôles'!$U$75<>"","C3","Défaut API")))) -> Défaut API | G43: =IF(B43="","",IF(E43="Exclusive",0,1)) -> 0 | H43: =IF(B43="","",IF(E43="Inclusive",1,0)) -> 0 | I43: 1 | J43: 0.1 | K43: 1.25 | L43: 5 | N43: =IF(B43="","",IF(N(L43)>0,I43/L43,0.2)) -> 0.2 | O43: =IF(B43="","",IF(N(L43)>0,J43/L43,0.02)) -> 0.02 | P43: =IF(B43="","",IF(N(L43)>0,IF(K43="",I43,K43)/L43,0.25)) -> 0.25 | Q43: claude-haiku-4-5 | R43: 6.1218155e-05 | S43: 1.2 | T43: 2.067979e-09 | U43: 1.8e-08 | V43: S | X43: =IF(B43="","",R43*S43*P_Mix/1000000+IF(P_Fab="Oui",T43,0)) -> 5.8218763e-09 | Y43: =IF(B43="","",IF(W43<>"",W43,IF(AND(P_Source="Table fournie",U43<>""),U43,X43))) -> 1.8e-08 | Z43: =IF(B43="","",IF(W43<>"","Forcé",IF(AND(P_Source="Table fournie",U43<>""),IF(V43="H","Table (hypothèse)","Table (sourcé)"),"Calculateur de Boris"))) -> Table (sourcé)
B44: Claude Haiku 5.5 | C44: Anthropic | E44: =IF(B44="","",IF(D44<>"",D44,IF('Contrôles'!$J$76>0,"Exclusive",IF('Contrôles'!$U$76<>"",'Contrôles'!$U$76,IFERROR(INDEX(F_Conv,MATCH(C44,F_Fam,0)),"Inclusive"))))) -> Exclusive | F44: =IF(B44="","",IF(D44<>"","Forcée",IF('Contrôles'!$J$76>0,"C2",IF('Contrôles'!$U$76<>"","C3","Défaut API")))) -> Défaut API | G44: =IF(B44="","",IF(E44="Exclusive",0,1)) -> 0 | H44: =IF(B44="","",IF(E44="Inclusive",1,0)) -> 0 | I44: 0.1 | J44: 0.01 | K44: 0.125 | L44: 0.5 | N44: =IF(B44="","",IF(N(L44)>0,I44/L44,0.2)) -> 0.2 | O44: =IF(B44="","",IF(N(L44)>0,J44/L44,0.02)) -> 0.02 | P44: =IF(B44="","",IF(N(L44)>0,IF(K44="",I44,K44)/L44,0.25)) -> 0.25 | Q44: claude-haiku-4-5 (proxy) | R44: 6.1218155e-05 | S44: 1.2 | T44: 2.067979e-09 | U44: 1.8e-08 | V44: H | X44: =IF(B44="","",R44*S44*P_Mix/1000000+IF(P_Fab="Oui",T44,0)) -> 5.8218763e-09 | Y44: =IF(B44="","",IF(W44<>"",W44,IF(AND(P_Source="Table fournie",U44<>""),U44,X44))) -> 1.8e-08 | Z44: =IF(B44="","",IF(W44<>"","Forcé",IF(AND(P_Source="Table fournie",U44<>""),IF(V44="H","Table (hypothèse)","Table (sourcé)"),"Calculateur de Boris"))) -> Table (hypothèse)
B45: Claude Sonnet 4 | C45: Anthropic | E45: =IF(B45="","",IF(D45<>"",D45,IF('Contrôles'!$J$77>0,"Exclusive",IF('Contrôles'!$U$77<>"",'Contrôles'!$U$77,IFERROR(INDEX(F_Conv,MATCH(C45,F_Fam,0)),"Inclusive"))))) -> Exclusive | F45: =IF(B45="","",IF(D45<>"","Forcée",IF('Contrôles'!$J$77>0,"C2",IF('Contrôles'!$U$77<>"","C3","Défaut API")))) -> Défaut API | G45: =IF(B45="","",IF(E45="Exclusive",0,1)) -> 0 | H45: =IF(B45="","",IF(E45="Inclusive",1,0)) -> 0 | I45: 3 | J45: 0.3 | K45: 3.75 | L45: 15 | N45: =IF(B45="","",IF(N(L45)>0,I45/L45,0.2)) -> 0.2 | O45: =IF(B45="","",IF(N(L45)>0,J45/L45,0.02)) -> 0.02 | P45: =IF(B45="","",IF(N(L45)>0,IF(K45="",I45,K45)/L45,0.25)) -> 0.25 | Q45: claude-sonnet-4 | R45: 0.0016896666 | S45: 1.2 | T45: 5.324451e-08 | U45: 4.9308e-07 | V45: S | X45: =IF(B45="","",R45*S45*P_Mix/1000000+IF(P_Fab="Oui",T45,0)) -> 1.5685487e-07 | Y45: =IF(B45="","",IF(W45<>"",W45,IF(AND(P_Source="Table fournie",U45<>""),U45,X45))) -> 4.9308e-07 | Z45: =IF(B45="","",IF(W45<>"","Forcé",IF(AND(P_Source="Table fournie",U45<>""),IF(V45="H","Table (hypothèse)","Table (sourcé)"),"Calculateur de Boris"))) -> Table (sourcé)
B46: Claude Sonnet 4.6 | C46: Anthropic | E46: =IF(B46="","",IF(D46<>"",D46,IF('Contrôles'!$J$78>0,"Exclusive",IF('Contrôles'!$U$78<>"",'Contrôles'!$U$78,IFERROR(INDEX(F_Conv,MATCH(C46,F_Fam,0)),"Inclusive"))))) -> Exclusive | F46: =IF(B46="","",IF(D46<>"","Forcée",IF('Contrôles'!$J$78>0,"C2",IF('Contrôles'!$U$78<>"","C3","Défaut API")))) -> Défaut API | G46: =IF(B46="","",IF(E46="Exclusive",0,1)) -> 0 | H46: =IF(B46="","",IF(E46="Inclusive",1,0)) -> 0 | I46: 3 | J46: 0.3 | K46: 3.75 | L46: 15 | N46: =IF(B46="","",IF(N(L46)>0,I46/L46,0.2)) -> 0.2 | O46: =IF(B46="","",IF(N(L46)>0,J46/L46,0.02)) -> 0.02 | P46: =IF(B46="","",IF(N(L46)>0,IF(K46="",I46,K46)/L46,0.25)) -> 0.25 | Q46: claude-sonnet-4-6 | R46: 0.0017018133 | S46: 1.2 | T46: 5.594532e-08 | U46: 4.4e-07 | V46: S | X46: =IF(B46="","",R46*S46*P_Mix/1000000+IF(P_Fab="Oui",T46,0)) -> 1.6030051e-07 | Y46: =IF(B46="","",IF(W46<>"",W46,IF(AND(P_Source="Table fournie",U46<>""),U46,X46))) -> 4.4e-07 | Z46: =IF(B46="","",IF(W46<>"","Forcé",IF(AND(P_Source="Table fournie",U46<>""),IF(V46="H","Table (hypothèse)","Table (sourcé)"),"Calculateur de Boris"))) -> Table (sourcé)
...

Sheet Contrôles
B2: Contrôles
B3: Contrôles de cohérence de la méthode (C1 à C6), sur toutes les données importées sauf C6 (année affichée).
B5: C1 · Complétude de l'import
B6: Lignes importées | C6: =MAX(0,COUNTA(D_Date)-1) -> 0
B7: Lignes avec une date lisible | C7: =COUNT(D_Jour) -> 0
B8: Lignes hors Copilot (exclues) | C8: =MAX(0,COUNTA(D_Prod)-1-COUNTIF(D_Prod,"*copilot*")) -> 0 | D8: =IF(C8>0,"⚠ Ces lignes ne sont pas comptées.","")
B9: Lignes sans aucun token | C9: =COUNTIFS(D_I,0,D_O,0,D_CR,0,D_CW,0) -> 0
B10: Lignes de modèles inconnus (« Autre modèle ») | C10: =COUNTIF(D_Grp,"(Autre modèle)") -> 0 | D10: =IF(C10>0,"⚠ Ajoutez ces modèles dans Calcul (ligne vide en bas de la table) ; en attendant ils utilisent la ligne « (Autre modèle) ».","✓ Tous les modèles sont reconnus.") -> ✓ Tous les modèles sont reconnus.
B11: Premier jour de données | C11: =S_First -> 46023
B12: Dernier jour de données | C12: =S_Last -> 46023
B14: C3 · Rapprochement des coûts par famille (montant brut ÷ coût recalculé)
B15: Pour chaque hypothèse de convention, le coût est recalculé avec la grille GitHub. La bonne hypothèse donne un rapport entre 0,90 et 1,00 (remises éventuelles). Calcul agrégé par famille.
B16: Famille | C16: Montant brut ($) | D16: Coût inclusive ($) | E16: Coût mixte ($) | F16: Coût exclusive ($) | G16: R inclusive | H16: R mixte | I16: R exclusive | J16: Décision C3
B17: Anthropic | C17: =SUMIF(K_Fam,B17,K_BrutP) -> 0 | D17: =SUMIF(K_Fam,B17,K_Ci) -> 0 | E17: =SUMIF(K_Fam,B17,K_Cm) -> 0 | F17: =SUMIF(K_Fam,B17,K_Ce) -> 0 | G17: =IF(D17>0,C17/D17,"") | H17: =IF(E17>0,C17/E17,"") | I17: =IF(F17>0,C17/F17,"") | J17: =IF(C17<=0,"",IF(AND(N(G17)>=0.895,N(G17)<=1.005),"Inclusive",IF(AND(N(H17)>=0.895,N(H17)<=1.005),"Mixte",IF(AND(N(I17)>=0.895,N(I17)<=1.005),"Exclusive",""))))
B18: OpenAI ≥ GPT-5.6 | C18: =SUMIF(K_Fam,B18,K_BrutP) -> 0 | D18: =SUMIF(K_Fam,B18,K_Ci) -> 0 | E18: =SUMIF(K_Fam,B18,K_Cm) -> 0 | F18: =SUMIF(K_Fam,B18,K_Ce) -> 0 | G18: =IF(D18>0,C18/D18,"") | H18: =IF(E18>0,C18/E18,"") | I18: =IF(F18>0,C18/F18,"") | J18: =IF(C18<=0,"",IF(AND(N(G18)>=0.895,N(G18)<=1.005),"Inclusive",IF(AND(N(H18)>=0.895,N(H18)<=1.005),"Mixte",IF(AND(N(I18)>=0.895,N(I18)<=1.005),"Exclusive",""))))
B19: OpenAI < GPT-5.6 | C19: =SUMIF(K_Fam,B19,K_BrutP) -> 0 | D19: =SUMIF(K_Fam,B19,K_Ci) -> 0 | E19: =SUMIF(K_Fam,B19,K_Cm) -> 0 | F19: =SUMIF(K_Fam,B19,K_Ce) -> 0 | G19: =IF(D19>0,C19/D19,"") | H19: =IF(E19>0,C19/E19,"") | I19: =IF(F19>0,C19/F19,"") | J19: =IF(C19<=0,"",IF(AND(N(G19)>=0.895,N(G19)<=1.005),"Inclusive",IF(AND(N(H19)>=0.895,N(H19)<=1.005),"Mixte",IF(AND(N(I19)>=0.895,N(I19)<=1.005),"Exclusive",""))))
B20: Google Gemini | C20: =SUMIF(K_Fam,B20,K_BrutP) -> 0 | D20: =SUMIF(K_Fam,B20,K_Ci) -> 0 | E20: =SUMIF(K_Fam,B20,K_Cm) -> 0 | F20: =SUMIF(K_Fam,B20,K_Ce) -> 0 | G20: =IF(D20>0,C20/D20,"") | H20: =IF(E20>0,C20/E20,"") | I20: =IF(F20>0,C20/F20,"") | J20: =IF(C20<=0,"",IF(AND(N(G20)>=0.895,N(G20)<=1.005),"Inclusive",IF(AND(N(H20)>=0.895,N(H20)<=1.005),"Mixte",IF(AND(N(I20)>=0.895,N(I20)<=1.005),"Exclusive",""))))
B21: xAI Grok | C21: =SUMIF(K_Fam,B21,K_BrutP) -> 0 | D21: =SUMIF(K_Fam,B21,K_Ci) -> 0 | E21: =SUMIF(K_Fam,B21,K_Cm) -> 0 | F21: =SUMIF(K_Fam,B21,K_Ce) -> 0 | G21: =IF(D21>0,C21/D21,"") | H21: =IF(E21>0,C21/E21,"") | I21: =IF(F21>0,C21/F21,"") | J21: =IF(C21<=0,"",IF(AND(N(G21)>=0.895,N(G21)<=1.005),"Inclusive",IF(AND(N(H21)>=0.895,N(H21)<=1.005),"Mixte",IF(AND(N(I21)>=0.895,N(I21)<=1.005),"Exclusive",""))))
B22: Moonshot Kimi | C22: =SUMIF(K_Fam,B22,K_BrutP) -> 0 | D22: =SUMIF(K_Fam,B22,K_Ci) -> 0 | E22: =SUMIF(K_Fam,B22,K_Cm) -> 0 | F22: =SUMIF(K_Fam,B22,K_Ce) -> 0 | G22: =IF(D22>0,C22/D22,"") | H22: =IF(E22>0,C22/E22,"") | I22: =IF(F22>0,C22/F22,"") | J22: =IF(C22<=0,"",IF(AND(N(G22)>=0.895,N(G22)<=1.005),"Inclusive",IF(AND(N(H22)>=0.895,N(H22)<=1.005),"Mixte",IF(AND(N(I22)>=0.895,N(I22)<=1.005),"Exclusive",""))))
B23: Microsoft MAI | C23: =SUMIF(K_Fam,B23,K_BrutP) -> 0 | D23: =SUMIF(K_Fam,B23,K_Ci) -> 0 | E23: =SUMIF(K_Fam,B23,K_Cm) -> 0 | F23: =SUMIF(K_Fam,B23,K_Ce) -> 0 | G23: =IF(D23>0,C23/D23,"") | H23: =IF(E23>0,C23/E23,"") | I23: =IF(F23>0,C23/F23,"") | J23: =IF(C23<=0,"",IF(AND(N(G23)>=0.895,N(G23)<=1.005),"Inclusive",IF(AND(N(H23)>=0.895,N(H23)<=1.005),"Mixte",IF(AND(N(I23)>=0.895,N(I23)<=1.005),"Exclusive",""))))
B24: Hors grille | C24: =SUMIF(K_Fam,B24,K_BrutP) -> 0 | D24: =SUMIF(K_Fam,B24,K_Ci) -> 0 | E24: =SUMIF(K_Fam,B24,K_Cm) -> 0 | F24: =SUMIF(K_Fam,B24,K_Ce) -> 0 | G24: =IF(D24>0,C24/D24,"") | H24: =IF(E24>0,C24/E24,"") | I24: =IF(F24>0,C24/F24,"") | J24: =IF(C24<=0,"",IF(AND(N(G24)>=0.895,N(G24)<=1.005),"Inclusive",IF(AND(N(H24)>=0.895,N(H24)<=1.005),"Mixte",IF(AND(N(I24)>=0.895,N(I24)<=1.005),"Exclusive",""))))
B27: C4 · Cas particuliers
B28: Lignes avec cache write non facturé (s_CW = s_I appliqué) | C28: =SUM(D_C4CW) -> 0
B29: Lignes où I − δ·CR − ε·CW < 0 (input frais ramené à 0) | C29: =SUM(D_C4F) -> 0 | D29: =IF(C29>0,"⚠ Vérifiez la convention des modèles concernés (colonne C4_input_frais_negatif de Données).","")
B31: C5 · Boucle globale des coûts
B32: Montant brut des modèles tarifés ($) | C32: =SUMIF(K_Cr,">0",K_BrutP) -> 0
B33: Coût recalculé, conventions appliquées ($) | C33: =SUM(K_Cr) -> 0
B34: Rapport | C34: =IF(C33>0,C32/C33,"") | D34: =IF(C33<=0,"",IF(AND(C34>=0.895,C34<=1.005),"✓ Dans la plage 0,90–1,00","⚠ Hors plage 0,90–1,00 : vérifier conventions, tarifs ou remises"))
B36: C6 · Sensibilité (année affichée) | C36: kgCO₂e | D36: Écart / central
B37: Résultat central | C37: =SUM(I_CO2) -> 0 | D37: =IF($C$37>0,C37/$C$37-1,"")
B38: Tout au Calculateur de Boris, mix retenu | C38: =SUMPRODUCT(I_TO,M_FEC) -> 0 | D38: =IF($C$37>0,C38/$C$37-1,"")
B39: Calculateur de Boris, France (2020, EEA) 51,1 g/kWh | C39: =SUMPRODUCT(I_TO,M_eO,M_PUE)*51.1/1000000+IF(P_Fab="Oui",SUMPRODUCT(I_TO,M_Fab),0) -> 0 | D39: =IF($C$37>0,C39/$C$37-1,"")
B40: Calculateur de Boris, Union européenne (2025, IEA) 170 g/kWh | C40: =SUMPRODUCT(I_TO,M_eO,M_PUE)*170/1000000+IF(P_Fab="Oui",SUMPRODUCT(I_TO,M_Fab),0) -> 0 | D40: =IF($C$37>0,C40/$C$37-1,"")
B41: Calculateur de Boris, Monde (2025, IEA) 435 g/kWh | C41: =SUMPRODUCT(I_TO,M_eO,M_PUE)*435/1000000+IF(P_Fab="Oui",SUMPRODUCT(I_TO,M_Fab),0) -> 0 | D41: =IF($C$37>0,C41/$C$37-1,"")
B42: Calculateur de Boris, mix retenu, sans fabrication | C42: =SUMPRODUCT(I_TO,M_eO,M_PUE)*P_Mix/1000000 -> 0 | D42: =IF($C$37>0,C42/$C$37-1,"")
B43: Fourchette basse (résultat central × basse) | C43: =C37*P_Lo -> 0 | D43: =IF($C$37>0,C43/$C$37-1,"")
B44: Fourchette haute (résultat central × haute) | C44: =C37*P_Hi -> 0 | D44: =IF($C$37>0,C44/$C$37-1,"")
B59: C2 et C3 par modèle (toutes données)
B60: C2 : si CR + CW dépasse I sur au moins une ligne, l'input ne contient pas le cache (convention exclusive). Coûts recalculés sans le plancher à 0 de l'input frais.
B61: Modèle | C61: Famille | D61: Lignes | E61: Σ input | F61: Σ cache read | G61: Σ cache write | H61: Σ output | I61: Montant brut ($) | J61: C2 : lignes cache > input | K61: Coût inclusive ($) | L61: Coût mixte ($) | M61: Coût exclusive ($) | N61: R inclusive | O61: R mixte | P61: R exclusive | Q61: Convention appliquée | R61: Coût retenu ($) | S61: R retenu | T61: Verdict | U61: Décision C3 (famille)
...

Sheet Méthodologie
B2: Méthodologie
B3: Méthode « Contrôle des tokens GitHub Copilot pour l'empreinte carbone de l'inférence » du 20 octobre 2026.
B5: Objet
B6: Le classeur estime l'empreinte carbone de l'inférence des modèles utilisés via GitHub Copilot, jour par jour, à partir de l'export « AI usage report ». C'est la déclinaison Excel du tableau de bord HTML : mêmes formules, mêmes facteurs, mêmes contrôles.
B8: Formules
B9: Input frais : F = max(0, I − δ·CR − ε·CW). Tokens équivalent output : T_O = F·s_I + CR·s_CR + CW·s_CW + O, chaque catégorie étant pondérée par son prix rapporté au prix de l'output du même modèle (s_I = P_I / P_O, etc.). Énergie : E = T_O × e_O × PUE / 1000. Empreinte : CO₂e = T_O × FE_token.
B11: Convention de l'input (δ, ε)
B12: GitHub ne documente pas si la colonne input de l'export contient déjà le cache. Pour chaque modèle : convention forcée dans Calcul, sinon C2 (si CR + CW dépasse I sur au moins une ligne, la convention est forcément exclusive), sinon C3 (rapprochement des coûts de la famille), sinon la convention documentée de l'API du fournisseur.
B14: Prix
B15: Grille GitHub du 20 octobre 2026, palier standard, en dollars par million de tokens. Le palier long contexte n'est pas identifiable dans l'export. Quand le cache write n'est pas facturé mais que CW > 0, s_CW = s_I. Le prix du cache read de Claude Sonnet 5.5 était de 0,20 $ avant le 1er octobre 2026 : les lignes antérieures utilisent la ligne « [ancien tarif] ». Claude Opus 4.5, 4.6, 4.7 et Claude Sonnet 4.5 ne figurent plus dans la grille GitHub : leurs tarifs publics de l'API Anthropic sont utilisés. Les modèles « Auto: X » utilisent les paramètres de X.
B17: Facteurs d'émission
